<?xml version='1.0' encoding='utf-8'?>
<robot name="right_shadow_hand">
  <link name="wrist" />
  <joint type="fixed" name="rh_wrist_joint">
    <parent link="wrist" />
    <child link="rh_palm" />
    <origin xyz="0.0 0.0 0.0" rpy="0.0 0.0 1.570796327" />
  </joint>
  <link name="rh_palm">
    <visual name="palm">
      <origin xyz="0.005374445170477271 -0.0022442906559082794 0.03201294312033412" rpy="0.2100458392356129 0.08313278223257159 1.5503210950325148" />
      <geometry>
        <mesh filename="stl/right_palm.stl" />
      </geometry>
      <material name="white" />
    </visual>
    <collision name="palm">
      <origin xyz="0.005374445170477271 -0.0022442906559082794 0.03201294312033412" rpy="0.2100458392356129 0.08313278223257159 1.5503210950325148" />
      <geometry>
        <mesh filename="stl/right_palm.stl" />
      </geometry>
    </collision>
  </link>
  <link name="rh_ffknuckle">
    <visual name="f_knuckle">
      <origin xyz="-8.015943942283821e-06 0.00028383334511582203 0.0003141144870240873" rpy="0.4761390295154802 0.007276744315003247 -0.01128884895567703" />
      <geometry>
        <mesh filename="stl/f_knuckle.stl" />
      </geometry>
      <material name="white" />
    </visual>
    <collision name="f_knuckle">
      <origin xyz="-8.015943942283821e-06 0.00028383334511582203 0.0003141144870240873" rpy="0.4761390295154802 0.007276744315003247 -0.01128884895567703" />
      <geometry>
        <mesh filename="stl/f_knuckle.stl" />
      </geometry>
    </collision>
  </link>
  <joint type="revolute" name="rh_FFJ4">
    <parent link="rh_palm" />
    <child link="rh_ffknuckle" />
    <origin xyz="0.033 0.0 0.095" rpy="0.0 0.0 0.0" />
    <axis xyz="0.0 -1.0 0.0" />
    <limit lower="-0.349066" upper="0.349066" effort="100" velocity="100" />
  </joint>
  <link name="rh_ffproximal">
    <visual name="f_proximal">
      <origin xyz="1.2104673000657597e-06 9.76175282387983e-06 0.022880653343431333" rpy="-7.135757573614219e-06 0.01189393423812235 1.5705980355726104" />
      <geometry>
        <mesh filename="stl/f_proximal.stl" />
      </geometry>
      <material name="white" />
    </visual>
    <collision name="f_proximal">
      <origin xyz="1.2104673000657597e-06 9.76175282387983e-06 0.022880653343431333" rpy="-7.135757573614219e-06 0.01189393423812235 1.5705980355726104" />
      <geometry>
        <mesh filename="stl/f_proximal.stl" />
      </geometry>
    </collision>
  </link>
  <joint type="revolute" name="rh_FFJ3">
    <parent link="rh_ffknuckle" />
    <child link="rh_ffproximal" />
    <origin xyz="0.0 0.0 0.0" rpy="0.0 0.0 0.0" />
    <axis xyz="1.0 0.0 0.0" />
    <limit lower="-0.261799" upper="1.5708" effort="100" velocity="100" />
  </joint>
  <link name="rh_ffmiddle">
    <visual name="f_middle">
      <origin xyz="-2.7197407046965675e-06 -3.219283283025054e-05 0.011511409944870538" rpy="-1.5154077996843905e-05 -0.00025673504362555555 1.5707963267948966" />
      <geometry>
        <mesh filename="stl/f_middle.stl" />
      </geometry>
      <material name="white" />
    </visual>
    <collision name="f_middle">
      <origin xyz="-2.7197407046965675e-06 -3.219283283025054e-05 0.011511409944870538" rpy="-1.5154077996843905e-05 -0.00025673504362555555 1.5707963267948966" />
      <geometry>
        <mesh filename="stl/f_middle.stl" />
      </geometry>
    </collision>
  </link>
  <joint type="revolute" name="rh_FFJ2">
    <parent link="rh_ffproximal" />
    <child link="rh_ffmiddle" />
    <origin xyz="0.0 0.0 0.045" rpy="0.0 0.0 0.0" />
    <axis xyz="1.0 0.0 0.0" />
    <limit lower="0.0" upper="1.5708" effort="100" velocity="100" />
  </joint>
  <link name="rh_ffdistal">
    <visual name="f_distal_pst">
      <origin xyz="-2.398434946392576e-05 0.00042073257364413626 0.017646475317320408" rpy="1.9593220200595154e-05 0.002689843516656243 1.582276007411751" />
      <geometry>
        <mesh filename="stl/f_distal_pst.stl" />
      </geometry>
      <material name="white" />
    </visual>
    <collision name="f_distal_pst">
      <origin xyz="-2.398434946392576e-05 0.00042073257364413626 0.017646475317320408" rpy="1.9593220200595154e-05 0.002689843516656243 1.582276007411751" />
      <geometry>
        <mesh filename="stl/f_distal_pst.stl" />
      </geometry>
    </collision>
  </link>
  <joint type="revolute" name="rh_FFJ1">
    <parent link="rh_ffmiddle" />
    <child link="rh_ffdistal" />
    <origin xyz="0.0 0.0 0.025" rpy="0.0 0.0 0.0" />
    <axis xyz="1.0 0.0 0.0" />
    <limit lower="0.0" upper="1.5708" effort="100" velocity="100" />
    <mimic joint="rh_FFJ2" multiplier="1" offset="0" />
  </joint>
  <link name="rh_mfknuckle">
    <visual name="f_knuckle">
      <origin xyz="-8.015943942283821e-06 0.00028383334511582203 0.0003141144870240873" rpy="0.4761390295154802 0.007276744315003247 -0.01128884895567703" />
      <geometry>
        <mesh filename="stl/f_knuckle.stl" />
      </geometry>
      <material name="white" />
    </visual>
    <collision name="f_knuckle">
      <origin xyz="-8.015943942283821e-06 0.00028383334511582203 0.0003141144870240873" rpy="0.4761390295154802 0.007276744315003247 -0.01128884895567703" />
      <geometry>
        <mesh filename="stl/f_knuckle.stl" />
      </geometry>
    </collision>
  </link>
  <joint type="revolute" name="rh_MFJ4">
    <parent link="rh_palm" />
    <child link="rh_mfknuckle" />
    <origin xyz="0.011 0.0 0.099" rpy="0.0 0.0 0.0" />
    <axis xyz="0.0 -1.0 0.0" />
    <limit lower="-0.349066" upper="0.349066" effort="100" velocity="100" />
  </joint>
  <link name="rh_mfproximal">
    <visual name="f_proximal">
      <origin xyz="1.2104673000657597e-06 9.76175282387983e-06 0.022880653343431333" rpy="-7.135757573614219e-06 0.01189393423812235 1.5705980355726104" />
      <geometry>
        <mesh filename="stl/f_proximal.stl" />
      </geometry>
      <material name="white" />
    </visual>
    <collision name="f_proximal">
      <origin xyz="1.2104673000657597e-06 9.76175282387983e-06 0.022880653343431333" rpy="-7.135757573614219e-06 0.01189393423812235 1.5705980355726104" />
      <geometry>
        <mesh filename="stl/f_proximal.stl" />
      </geometry>
    </collision>
  </link>
  <joint type="revolute" name="rh_MFJ3">
    <parent link="rh_mfknuckle" />
    <child link="rh_mfproximal" />
    <origin xyz="0.0 0.0 0.0" rpy="0.0 0.0 0.0" />
    <axis xyz="1.0 0.0 0.0" />
    <limit lower="-0.261799" upper="1.5708" effort="100" velocity="100" />
  </joint>
  <link name="rh_mfmiddle">
    <visual name="f_middle">
      <origin xyz="-2.7197407046965675e-06 -3.219283283025054e-05 0.011511409944870538" rpy="-1.5154077996843905e-05 -0.00025673504362555555 1.5707963267948966" />
      <geometry>
        <mesh filename="stl/f_middle.stl" />
      </geometry>
      <material name="white" />
    </visual>
    <collision name="f_middle">
      <origin xyz="-2.7197407046965675e-06 -3.219283283025054e-05 0.011511409944870538" rpy="-1.5154077996843905e-05 -0.00025673504362555555 1.5707963267948966" />
      <geometry>
        <mesh filename="stl/f_middle.stl" />
      </geometry>
    </collision>
  </link>
  <joint type="revolute" name="rh_MFJ2">
    <parent link="rh_mfproximal" />
    <child link="rh_mfmiddle" />
    <origin xyz="0.0 0.0 0.045" rpy="0.0 0.0 0.0" />
    <axis xyz="1.0 0.0 0.0" />
    <limit lower="0.0" upper="1.5708" effort="100" velocity="100" />
  </joint>
  <link name="rh_mfdistal">
    <visual name="f_distal_pst">
      <origin xyz="-2.398434946392576e-05 0.00042073257364413626 0.017646475317320408" rpy="1.9593220200595154e-05 0.002689843516656243 1.582276007411751" />
      <geometry>
        <mesh filename="stl/f_distal_pst.stl" />
      </geometry>
      <material name="white" />
    </visual>
    <collision name="f_distal_pst">
      <origin xyz="-2.398434946392576e-05 0.00042073257364413626 0.017646475317320408" rpy="1.9593220200595154e-05 0.002689843516656243 1.582276007411751" />
      <geometry>
        <mesh filename="stl/f_distal_pst.stl" />
      </geometry>
    </collision>
  </link>
  <joint type="revolute" name="rh_MFJ1">
    <parent link="rh_mfmiddle" />
    <child link="rh_mfdistal" />
    <origin xyz="0.0 0.0 0.025" rpy="0.0 0.0 0.0" />
    <axis xyz="1.0 0.0 0.0" />
    <limit lower="0.0" upper="1.5708" effort="100" velocity="100" />
    <mimic joint="rh_MFJ2" multiplier="1" offset="0" />
  </joint>
  <link name="rh_rfknuckle">
    <visual name="f_knuckle">
      <origin xyz="-8.015943942283821e-06 0.00028383334511582203 0.0003141144870240873" rpy="0.4761390295154802 0.007276744315003247 -0.01128884895567703" />
      <geometry>
        <mesh filename="stl/f_knuckle.stl" />
      </geometry>
      <material name="white" />
    </visual>
    <collision name="f_knuckle">
      <origin xyz="-8.015943942283821e-06 0.00028383334511582203 0.0003141144870240873" rpy="0.4761390295154802 0.007276744315003247 -0.01128884895567703" />
      <geometry>
        <mesh filename="stl/f_knuckle.stl" />
      </geometry>
    </collision>
  </link>
  <joint type="revolute" name="rh_RFJ4">
    <parent link="rh_palm" />
    <child link="rh_rfknuckle" />
    <origin xyz="-0.011 0.0 0.095" rpy="0.0 0.0 0.0" />
    <axis xyz="0.0 1.0 0.0" />
    <limit lower="-0.349066" upper="0.349066" effort="100" velocity="100" />
  </joint>
  <link name="rh_rfproximal">
    <visual name="f_proximal">
      <origin xyz="1.2104673000657597e-06 9.76175282387983e-06 0.022880653343431333" rpy="-7.135757573614219e-06 0.01189393423812235 1.5705980355726104" />
      <geometry>
        <mesh filename="stl/f_proximal.stl" />
      </geometry>
      <material name="white" />
    </visual>
    <collision name="f_proximal">
      <origin xyz="1.2104673000657597e-06 9.76175282387983e-06 0.022880653343431333" rpy="-7.135757573614219e-06 0.01189393423812235 1.5705980355726104" />
      <geometry>
        <mesh filename="stl/f_proximal.stl" />
      </geometry>
    </collision>
  </link>
  <joint type="revolute" name="rh_RFJ3">
    <parent link="rh_rfknuckle" />
    <child link="rh_rfproximal" />
    <origin xyz="0.0 0.0 0.0" rpy="0.0 0.0 0.0" />
    <axis xyz="1.0 0.0 0.0" />
    <limit lower="-0.261799" upper="1.5708" effort="100" velocity="100" />
  </joint>
  <link name="rh_rfmiddle">
    <visual name="f_middle">
      <origin xyz="-2.7197407046965675e-06 -3.219283283025054e-05 0.011511409944870538" rpy="-1.5154077996843905e-05 -0.00025673504362555555 1.5707963267948966" />
      <geometry>
        <mesh filename="stl/f_middle.stl" />
      </geometry>
      <material name="white" />
    </visual>
    <collision name="f_middle">
      <origin xyz="-2.7197407046965675e-06 -3.219283283025054e-05 0.011511409944870538" rpy="-1.5154077996843905e-05 -0.00025673504362555555 1.5707963267948966" />
      <geometry>
        <mesh filename="stl/f_middle.stl" />
      </geometry>
    </collision>
  </link>
  <joint type="revolute" name="rh_RFJ2">
    <parent link="rh_rfproximal" />
    <child link="rh_rfmiddle" />
    <origin xyz="0.0 0.0 0.045" rpy="0.0 0.0 0.0" />
    <axis xyz="1.0 0.0 0.0" />
    <limit lower="0.0" upper="1.5708" effort="100" velocity="100" />
  </joint>
  <link name="rh_rfdistal">
    <visual name="f_distal_pst">
      <origin xyz="-2.398434946392576e-05 0.00042073257364413626 0.017646475317320408" rpy="1.9593220200595154e-05 0.002689843516656243 1.582276007411751" />
      <geometry>
        <mesh filename="stl/f_distal_pst.stl" />
      </geometry>
      <material name="white" />
    </visual>
    <collision name="f_distal_pst">
      <origin xyz="-2.398434946392576e-05 0.00042073257364413626 0.017646475317320408" rpy="1.9593220200595154e-05 0.002689843516656243 1.582276007411751" />
      <geometry>
        <mesh filename="stl/f_distal_pst.stl" />
      </geometry>
    </collision>
  </link>
  <joint type="revolute" name="rh_RFJ1">
    <parent link="rh_rfmiddle" />
    <child link="rh_rfdistal" />
    <origin xyz="0.0 0.0 0.025" rpy="0.0 0.0 0.0" />
    <axis xyz="1.0 0.0 0.0" />
    <limit lower="0.0" upper="1.5708" effort="100" velocity="100" />
    <mimic joint="rh_RFJ2" multiplier="1" offset="0" />
  </joint>
  <link name="rh_lfmetacarpal">
    <visual name="lf_metacarpal">
      <origin xyz="-0.01889428  0.00066234  0.03130367" rpy="-0.8420695670279069 0.04469723682216371 1.565424596377065" />
      <geometry>
        <mesh filename="stl/right_lf_metacarpal.stl" />
      </geometry>
      <material name="white" />
    </visual>
    <collision name="lf_metacarpal">
      <origin xyz="-0.01889428  0.00066234  0.03130367" rpy="-0.8420695670279069 0.04469723682216371 1.565424596377065" />
      <geometry>
        <mesh filename="stl/right_lf_metacarpal.stl" />
      </geometry>
    </collision>
  </link>
  <joint type="revolute" name="rh_LFJ5">
    <parent link="rh_palm" />
    <child link="rh_lfmetacarpal" />
    <origin xyz="-0.033 0.0 0.02071" rpy="0 0.6108649061631908 0" />
    <axis xyz="0 0 1" />
    <limit lower="0.0" upper="0.785398" effort="100" velocity="100" />
  </joint>
  <link name="rh_lfknuckle">
    <visual name="f_knuckle">
      <origin xyz="-8.015943942283821e-06 0.00028383334511582203 0.0003141144870240873" rpy="0.4761390295154802 0.007276744315003247 -0.01128884895567703" />
      <geometry>
        <mesh filename="stl/f_knuckle.stl" />
      </geometry>
      <material name="white" />
    </visual>
    <collision name="f_knuckle">
      <origin xyz="-8.015943942283821e-06 0.00028383334511582203 0.0003141144870240873" rpy="0.4761390295154802 0.007276744315003247 -0.01128884895567703" />
      <geometry>
        <mesh filename="stl/f_knuckle.stl" />
      </geometry>
    </collision>
  </link>
  <joint type="revolute" name="rh_LFJ4">
    <parent link="rh_lfmetacarpal" />
    <child link="rh_lfknuckle" />
    <origin xyz="-0.03773558 0. 0.05389203" rpy="0 -0.6108649061631908 0" />
    <axis xyz="0.0 1.0 0.0" />
    <limit lower="-0.349066" upper="0.349066" effort="100" velocity="100" />
  </joint>
  <link name="rh_lfproximal">
    <visual name="f_proximal">
      <origin xyz="1.2104673000657597e-06 9.76175282387983e-06 0.022880653343431333" rpy="-7.135757573614219e-06 0.01189393423812235 1.5705980355726104" />
      <geometry>
        <mesh filename="stl/f_proximal.stl" />
      </geometry>
      <material name="white" />
    </visual>
    <collision name="f_proximal">
      <origin xyz="1.2104673000657597e-06 9.76175282387983e-06 0.022880653343431333" rpy="-7.135757573614219e-06 0.01189393423812235 1.5705980355726104" />
      <geometry>
        <mesh filename="stl/f_proximal.stl" />
      </geometry>
    </collision>
  </link>
  <joint type="revolute" name="rh_LFJ3">
    <parent link="rh_lfknuckle" />
    <child link="rh_lfproximal" />
    <origin xyz="0.0 0.0 0.0" rpy="0.0 0.0 0.0" />
    <axis xyz="1.0 0.0 0.0" />
    <limit lower="-0.261799" upper="1.5708" effort="100" velocity="100" />
  </joint>
  <link name="rh_lfmiddle">
    <visual name="f_middle">
      <origin xyz="-2.7197407046965675e-06 -3.219283283025054e-05 0.011511409944870538" rpy="-1.5154077996843905e-05 -0.00025673504362555555 1.5707963267948966" />
      <geometry>
        <mesh filename="stl/f_middle.stl" />
      </geometry>
      <material name="white" />
    </visual>
    <collision name="f_middle">
      <origin xyz="-2.7197407046965675e-06 -3.219283283025054e-05 0.011511409944870538" rpy="-1.5154077996843905e-05 -0.00025673504362555555 1.5707963267948966" />
      <geometry>
        <mesh filename="stl/f_middle.stl" />
      </geometry>
    </collision>
  </link>
  <joint type="revolute" name="rh_LFJ2">
    <parent link="rh_lfproximal" />
    <child link="rh_lfmiddle" />
    <origin xyz="0.0 0.0 0.045" rpy="0.0 0.0 0.0" />
    <axis xyz="1.0 0.0 0.0" />
    <limit lower="0.0" upper="1.5708" effort="100" velocity="100" />
  </joint>
  <link name="rh_lfdistal">
    <visual name="f_distal_pst">
      <origin xyz="-2.398434946392576e-05 0.00042073257364413626 0.017646475317320408" rpy="1.9593220200595154e-05 0.002689843516656243 1.582276007411751" />
      <geometry>
        <mesh filename="stl/f_distal_pst.stl" />
      </geometry>
      <material name="white" />
    </visual>
    <collision name="f_distal_pst">
      <origin xyz="-2.398434946392576e-05 0.00042073257364413626 0.017646475317320408" rpy="1.9593220200595154e-05 0.002689843516656243 1.582276007411751" />
      <geometry>
        <mesh filename="stl/f_distal_pst.stl" />
      </geometry>
    </collision>
  </link>
  <joint type="revolute" name="rh_LFJ1">
    <parent link="rh_lfmiddle" />
    <child link="rh_lfdistal" />
    <origin xyz="0.0 0.0 0.025" rpy="0.0 0.0 0.0" />
    <axis xyz="1.0 0.0 0.0" />
    <limit lower="0.0" upper="1.5708" effort="100" velocity="100" />
    <mimic joint="rh_LFJ2" multiplier="1" offset="0" />
  </joint>
  <link name="rh_thbase" />
  <joint type="revolute" name="rh_THJ5">
    <parent link="rh_palm" />
    <child link="rh_thbase" />
    <origin xyz="0.034 -0.00858 0.029" rpy="0.0 0.7853970066908715 0.0" />
    <axis xyz="0.0 0.0 -1.0" />
    <limit lower="-1.0472" upper="1.0472" effort="100" velocity="100" />
  </joint>
  <link name="rh_thproximal">
    <visual name="th_proximal">
      <origin xyz="-6.378894056540728e-06 -2.6031284627244637e-05 0.016715298411459745" rpy="-4.186875454471058e-06 0.0010962409823094266 0.3847587823606159" />
      <geometry>
        <mesh filename="stl/th_proximal.stl" />
      </geometry>
      <material name="white" />
    </visual>
    <collision name="th_proximal">
      <origin xyz="-6.378894056540728e-06 -2.6031284627244637e-05 0.016715298411459745" rpy="-4.186875454471058e-06 0.0010962409823094266 0.3847587823606159" />
      <geometry>
        <mesh filename="stl/th_proximal.stl" />
      </geometry>
    </collision>
  </link>
  <joint type="revolute" name="rh_THJ4">
    <parent link="rh_thbase" />
    <child link="rh_thproximal" />
    <origin xyz="0.0 0.0 0.0" rpy="0.0 0.0 0.0" />
    <axis xyz="1.0 0.0 0.0" />
    <limit lower="0.0" upper="1.22173" effort="100" velocity="100" />
  </joint>
  <link name="rh_thhub" />
  <joint type="revolute" name="rh_THJ3">
    <parent link="rh_thproximal" />
    <child link="rh_thhub" />
    <origin xyz="0.0 0.0 0.038" rpy="0.0 0.0 0.0" />
    <axis xyz="1.0 0.0 0.0" />
    <limit lower="-0.20944" upper="0.20944" effort="100" velocity="100" />
  </joint>
  <link name="rh_thmiddle">
    <visual name="th_middle">
      <origin xyz="7.479629857400793e-05 -4.506977852869377e-05 0.015348398308984388" rpy="0.0 -0.0009035488116579948 0.0" />
      <geometry>
        <mesh filename="stl/th_middle.stl" />
      </geometry>
      <material name="white" />
    </visual>
    <collision name="th_middle">
      <origin xyz="7.479629857400793e-05 -4.506977852869377e-05 0.015348398308984388" rpy="0.0 -0.0009035488116579948 0.0" />
      <geometry>
        <mesh filename="stl/th_middle.stl" />
      </geometry>
    </collision>
  </link>
  <joint type="revolute" name="rh_THJ2">
    <parent link="rh_thhub" />
    <child link="rh_thmiddle" />
    <origin xyz="0.0 0.0 0.0" rpy="0.0 0.0 0.0" />
    <axis xyz="0.0 -1.0 0.0" />
    <limit lower="-0.698132" upper="0.698132" effort="100" velocity="100" />
  </joint>
  <link name="rh_thdistal">
    <visual name="th_distal_pst">
      <origin xyz="-8.254509753145168e-07 0.000802518759472585 0.019553373143358997" rpy="-0.0001073181947076323 0.003173495876248822 1.5706693697416252" />
      <geometry>
        <mesh filename="stl/th_distal_pst.stl" />
      </geometry>
      <material name="white" />
    </visual>
    <collision name="th_distal_pst">
      <origin xyz="-8.254509753145168e-07 0.000802518759472585 0.019553373143358997" rpy="-0.0001073181947076323 0.003173495876248822 1.5706693697416252" />
      <geometry>
        <mesh filename="stl/th_distal_pst.stl" />
      </geometry>
    </collision>
  </link>
  <joint type="revolute" name="rh_THJ1">
    <parent link="rh_thmiddle" />
    <child link="rh_thdistal" />
    <origin xyz="0.0 0.0 0.032" rpy="0.0 0.0 -1.5707963267948963" />
    <axis xyz="1.0 0.0 0.0" />
    <limit lower="-0.261799" upper="1.5708" effort="100" velocity="100" />
  </joint>
  <material name="white">
    <color rgba="1 1 1 1" />
  </material>
  <link name="rh_fftip" type="fixed" />
  <joint type="fixed" name="rh_FFTIP">
    <parent link="rh_ffdistal" />
    <child link="rh_fftip" />
    <origin xyz="0.0 0.0 0.026" rpy="0.0 0.0 0.0" />
  </joint>
  <link name="rh_mftip" type="fixed" />
  <joint type="fixed" name="rh_MFTIP">
    <parent link="rh_mfdistal" />
    <child link="rh_mftip" />
    <origin xyz="0.0 0.0 0.026" rpy="0.0 0.0 0.0" />
  </joint>
  <link name="rh_rftip" type="fixed" />
  <joint type="fixed" name="rh_RFTIP">
    <parent link="rh_rfdistal" />
    <child link="rh_rftip" />
    <origin xyz="0.0 0.0 0.026" rpy="0.0 0.0 0.0" />
  </joint>
  <link name="rh_lftip" type="fixed" />
  <joint type="fixed" name="rh_LFTIP">
    <parent link="rh_lfdistal" />
    <child link="rh_lftip" />
    <origin xyz="0.0 0.0 0.026" rpy="0.0 0.0 0.0" />
  </joint>
  <link name="rh_thtip" type="fixed" />
  <joint type="fixed" name="rh_THTIP">
    <parent link="rh_thdistal" />
    <child link="rh_thtip" />
    <origin xyz="0.0 0.0 0.0275" rpy="0.0 0.0 0.0" />
  </joint>
</robot>